<?xml version="1.0"?>
<robot name="abb_irb6660_205_190" xmlns:xacro="http://ros.org/wiki/xacro">
  <!-- <xacro:include filename="$(find abb_resources)/urdf/common_materials.xacro"/> -->

    <!-- link list -->
    <link name="base_link">
      <visual>
        <origin xyz="0 0 0" rpy="0 0 0"/>
        <geometry>
          <mesh filename="package://abb_irb6660_support/meshes/irb6660/visual/base_link.stl"/>
        </geometry>
        <material name="abb_orange">
            <color rgba="0.7372549 0.3490196 0.1607843 1" />
        </material>
      </visual>

      <collision>
        <geometry>
          <mesh filename="package://abb_irb6660_support/meshes/irb6660/collision/base_link.stl"/>
        </geometry>
        <material name="abb_yellow">
          <color rgba="1 1 0 1" />
        </material>
      </collision>

      <inertial>
        <mass value="0.1" />
        <inertia ixx="0.03" iyy="0.03" izz="0.03" ixy="0.0" ixz="0.0" iyz="0.0" />
      </inertial>
    </link>

    <link name="link_1">
      <visual>
        <origin xyz="0 0 0" rpy="0 0 0"/>
        <geometry>
          <mesh filename="package://abb_irb6660_support/meshes/irb6660/visual/link_1.stl"/>
        </geometry>
        <material name="abb_orange">
          <color rgba="0.7372549 0.3490196 0.1607843 1" />
        </material>
      </visual>
      
      <collision>
        <origin xyz="0 0 0" rpy="0 0 0"/>
        <geometry>
          <mesh filename="package://abb_irb6660_support/meshes/irb6660/collision/link_1.stl"/>
        </geometry>
        <material name="abb_yellow">
          <color rgba="1 1 0 1" />
        </material>
      </collision>
      
      <inertial>
        <mass value="0.1" />
        <inertia ixx="0.03" iyy="0.03" izz="0.03" ixy="0.0" ixz="0.0" iyz="0.0" />
      </inertial>
    </link>

    <link name="link_2">
      <visual>
        <origin xyz="0 0 0" rpy="0 0 0"/>
        <geometry>
          <mesh filename="package://abb_irb6660_support/meshes/irb6660_205_190/visual/link_2.stl"/>
        </geometry>
        <material name="abb_orange">
          <color rgba="0.7372549 0.3490196 0.1607843 1" />
        </material>
      </visual>
      
      <collision>
        <origin xyz="0 0 0" rpy="0 0 0"/>
        <geometry>
          <mesh filename="package://abb_irb6660_support/meshes/irb6660_205_190/collision/link_2.stl"/>
        </geometry>
        <material name="abb_yellow">
          <color rgba="1 1 0 1" />
        </material>
      </collision>
      
      <inertial>
        <mass value="0.1" />
        <inertia ixx="0.03" iyy="0.03" izz="0.03" ixy="0.0" ixz="0.0" iyz="0.0" />
      </inertial>
    </link>
    <link name="link_3">
      <visual>
        <origin xyz="0 0 0" rpy="0 0 0"/>
        <geometry>
          <mesh filename="package://abb_irb6660_support/meshes/irb6660/visual/link_3.stl"/>
        </geometry>
        <material name="abb_orange">
          <color rgba="0.7372549 0.3490196 0.1607843 1" />
        </material>
      </visual>
      
      <collision>
        <origin xyz="0 0 0" rpy="0 0 0"/>
        <geometry>
          <mesh filename="package://abb_irb6660_support/meshes/irb6660/collision/link_3.stl"/>
        </geometry>
        <material name="abb_yellow">
          <color rgba="1 1 0 1" />
        </material>
      </collision>
      
      <inertial>
        <mass value="0.1" />
        <inertia ixx="0.03" iyy="0.03" izz="0.03" ixy="0.0" ixz="0.0" iyz="0.0" />
      </inertial>
    </link>

    <link name="link_4">
      <visual>
        <origin xyz="0 0 0" rpy="0 0 0"/>
        <geometry>
          <mesh filename="package://abb_irb6660_support/meshes/irb6660_205_190/visual/link_4.stl"/>
        </geometry>
        <material name="abb_orange">
          <color rgba="0.7372549 0.3490196 0.1607843 1" />
        </material>
      </visual>

      <collision>
        <origin xyz="0 0 0" rpy="0 0 0"/>
        <geometry>
            <mesh filename="package://abb_irb6660_support/meshes/irb6660_205_190/collision/link_4.stl"/>
        </geometry>
        <material name="abb_yellow">
          <color rgba="1 1 0 1" />
        </material>
      </collision>
      <inertial>
        <mass value="0.1" />
        <inertia ixx="0.03" iyy="0.03" izz="0.03" ixy="0.0" ixz="0.0" iyz="0.0" />
      </inertial>
    </link>

    <link name="link_5">
      <visual>
        <origin xyz="0 0 0" rpy="0 0 0"/>
        <geometry>
          <mesh filename="package://abb_irb6660_support/meshes/irb6660/visual/link_5.stl"/>
        </geometry>
        <material name="abb_orange">
          <color rgba="0.7372549 0.3490196 0.1607843 1" />
        </material>
      </visual>

      <collision>
        <origin xyz="0 0 0" rpy="0 0 0"/>
        <geometry>
          <mesh filename="package://abb_irb6660_support/meshes/irb6660/collision/link_5.stl"/>
        </geometry>
        <material name="abb_yellow">
          <color rgba="1 1 0 1" />
        </material>
      </collision>

      <inertial>
        <mass value="0.1" />
        <inertia ixx="0.03" iyy="0.03" izz="0.03" ixy="0.0" ixz="0.0" iyz="0.0" />
      </inertial>
    </link>

    <link name="link_6">
      <visual>
        <origin xyz="0 0 0" rpy="0 0 0"/>
        <geometry>
          <mesh filename="package://abb_irb6660_support/meshes/irb6660/visual/link_6.stl"/>
        </geometry>
        <material name="abb_orange">
          <color rgba="0.7372549 0.3490196 0.1607843 1" />
        </material>
      </visual>

      <collision>
        <origin xyz="0 0 0" rpy="0 0 0"/>
        <geometry>
          <mesh filename="package://abb_irb6660_support/meshes/irb6660/collision/link_6.stl"/>
        </geometry>
        <material name="abb_yellow">
          <color rgba="1 1 0 1" />
        </material>
      </collision>

      <inertial>
        <mass value="0.1" />
        <inertia ixx="0.03" iyy="0.03" izz="0.03" ixy="0.0" ixz="0.0" iyz="0.0" />
      </inertial>
    </link>
    <link name="tool0"/>
    <!-- end of link list -->

    <!-- joint list -->
    <joint name="joint_1" type="revolute">
        <origin rpy="0 0 0" xyz="0 0 0.8145" />
        <parent link="base_link" />
        <child link="link_1" />
        <axis xyz="0 0 1" />
        <limit effort="500.0" lower="-3.14159265359" upper="3.14159265359" velocity="2.26892802759" />
    </joint>

    <joint name="joint_2" type="revolute">
        <origin rpy="0 0 0" xyz="0.300 0 0" />
        <parent link="link_1" />
        <child link="link_2" />
        <axis xyz="0 1 0" />
        <limit effort="500.0" lower="-0.733038285838" upper="1.4835298642" velocity="2.26892802759" />
    </joint>

    <joint name="joint_3" type="revolute">
        <origin rpy="0 0 0" xyz="0 0 0.700" />
        <parent link="link_2" />
        <child link="link_3" />
        <axis xyz="0 1 0" />
        <limit effort="500.0" lower="-1.2217304764" upper="1.2217304764" velocity="2.26892802759" />
    </joint>

    <joint name="joint_4" type="revolute">
        <origin rpy="0 0 0" xyz="0 0 0.280" />
        <parent link="link_3" />
        <child link="link_4" />
        <axis xyz="1 0 0" />
        <limit effort="500.0" lower="-5.23598775598" upper="5.23598775598" velocity="2.61799387799" />
    </joint>

    <joint name="joint_5" type="revolute">
        <origin rpy="0 0 0" xyz="0.893 0 0" />
        <parent link="link_4" />
        <child link="link_5" />
        <axis xyz="0 1 0" />
        <limit effort="500.0" lower="-2.09439510239" upper="2.09439510239" velocity="2.09439510239" />
    </joint>

    <joint name="joint_6" type="revolute">
        <origin rpy="0 0 0" xyz="0.200 0 0" />
        <parent link="link_5" />
        <child link="link_6" />
        <axis xyz="1 0 0" />
        <limit effort="500.0" lower="-6.28318530718" upper="6.28318530718" velocity="3.31612557879" />
    </joint>

    <joint name="joint_6-tool0" type="fixed">
        <origin rpy="0 1.57079632679 0" xyz="0 0 0" />
        <parent link="link_6" />
        <child link="tool0" />
    </joint>
    <!-- end of joint list -->

    <!-- ROS base_link to ABB World Coordinates transform -->
    <link name="base" />
    <joint name="base_link-base" type="fixed">
      <origin xyz="0 0 0" rpy="0 0 0"/>
      <parent link="base_link"/>
      <child link="base"/>
    </joint>

    <link name="world" />
    <joint name="fixed" type="fixed">
        <origin rpy="0 0 0" xyz="0 0 0" />
        <parent link="world" />
        <child link="base_link" />
    </joint>

    <!-- Transmissions -->

    <!-- POSITION CONTROLLER -->
    <!-- <transmission name="trans_joint_1">
      <type>transmission_interface/SimpleTransmission</type>
      <joint name="joint_1">
        <hardwareInterface>hardware_interface/PositionJointInterface</hardwareInterface>
      </joint>
      <actuator name="joint_1_motor">
        <hardwareInterface>hardware_interface/PositionJointInterface</hardwareInterface>
        <mechanicalReduction>1</mechanicalReduction>
      </actuator>
    </transmission>

    <transmission name="trans_joint_2">
      <type>transmission_interface/SimpleTransmission</type>
      <joint name="joint_2">
        <hardwareInterface>hardware_interface/PositionJointInterface</hardwareInterface>
      </joint>
      <actuator name="joint_2_motor">
        <hardwareInterface>hardware_interface/PositionJointInterface</hardwareInterface>
        <mechanicalReduction>1</mechanicalReduction>
      </actuator>
    </transmission>

    <transmission name="trans_joint_3">
      <type>transmission_interface/SimpleTransmission</type>
      <joint name="joint_3">
        <hardwareInterface>hardware_interface/PositionJointInterface</hardwareInterface>
      </joint>
      <actuator name="joint_3_motor">
        <hardwareInterface>hardware_interface/PositionJointInterface</hardwareInterface>
        <mechanicalReduction>1</mechanicalReduction>
      </actuator>
    </transmission>

    <transmission name="trans_joint_4">
      <type>transmission_interface/SimpleTransmission</type>
      <joint name="joint_4">
        <hardwareInterface>hardware_interface/PositionJointInterface</hardwareInterface>
      </joint>
      <actuator name="joint_4_motor">
        <hardwareInterface>hardware_interface/PositionJointInterface</hardwareInterface>
        <mechanicalReduction>1</mechanicalReduction>
      </actuator>
    </transmission>
    
    <transmission name="trans_joint_5">
      <type>transmission_interface/SimpleTransmission</type>
      <joint name="joint_5">
        <hardwareInterface>hardware_interface/PositionJointInterface</hardwareInterface>
      </joint>
      <actuator name="joint_5_motor">
        <hardwareInterface>hardware_interface/PositionJointInterface</hardwareInterface>
        <mechanicalReduction>1</mechanicalReduction>
      </actuator>
    </transmission>

    <transmission name="trans_joint_6">
      <type>transmission_interface/SimpleTransmission</type>
      <joint name="joint_6">
        <hardwareInterface>hardware_interface/PositionJointInterface</hardwareInterface>
      </joint>
      <actuator name="joint_6_motor">
        <hardwareInterface>hardware_interface/PositionJointInterface</hardwareInterface>
        <mechanicalReduction>1</mechanicalReduction>
      </actuator>
    </transmission> -->

    <!-- VELOCITY CONTROLLER -->

    <transmission name="trans_joint_1">
      <type>transmission_interface/SimpleTransmission</type>
      <joint name="joint_1">
        <hardwareInterface>hardware_interface/VelocityJointInterface</hardwareInterface>
      </joint>
      <actuator name="joint_1_motor">
        <hardwareInterface>hardware_interface/VelocityJointInterface</hardwareInterface>
        <mechanicalReduction>1</mechanicalReduction>
      </actuator>
    </transmission>

    <transmission name="trans_joint_2">
      <type>transmission_interface/SimpleTransmission</type>
      <joint name="joint_2">
        <hardwareInterface>hardware_interface/VelocityJointInterface</hardwareInterface>
      </joint>
      <actuator name="joint_2_motor">
        <hardwareInterface>hardware_interface/VelocityJointInterface</hardwareInterface>
        <mechanicalReduction>1</mechanicalReduction>
      </actuator>
    </transmission>

    <transmission name="trans_joint_3">
      <type>transmission_interface/SimpleTransmission</type>
      <joint name="joint_3">
        <hardwareInterface>hardware_interface/VelocityJointInterface</hardwareInterface>
      </joint>
      <actuator name="joint_3_motor">
        <hardwareInterface>hardware_interface/VelocityJointInterface</hardwareInterface>
        <mechanicalReduction>1</mechanicalReduction>
      </actuator>
    </transmission>

    <transmission name="trans_joint_4">
      <type>transmission_interface/SimpleTransmission</type>
      <joint name="joint_4">
        <hardwareInterface>hardware_interface/VelocityJointInterface</hardwareInterface>
      </joint>
      <actuator name="joint_4_motor">
        <hardwareInterface>hardware_interface/VelocityJointInterface</hardwareInterface>
        <mechanicalReduction>1</mechanicalReduction>
      </actuator>
    </transmission>
    
    <transmission name="trans_joint_5">
      <type>transmission_interface/SimpleTransmission</type>
      <joint name="joint_5">
        <hardwareInterface>hardware_interface/VelocityJointInterface</hardwareInterface>
      </joint>
      <actuator name="joint_5_motor">
        <hardwareInterface>hardware_interface/VelocityJointInterface</hardwareInterface>
        <mechanicalReduction>1</mechanicalReduction>
      </actuator>
    </transmission>

    <transmission name="trans_joint_6">
      <type>transmission_interface/SimpleTransmission</type>
      <joint name="joint_6">
        <hardwareInterface>hardware_interface/VelocityJointInterface</hardwareInterface>
      </joint>
      <actuator name="joint_6_motor">
        <hardwareInterface>hardware_interface/VelocityJointInterface</hardwareInterface>
        <mechanicalReduction>1</mechanicalReduction>
      </actuator>
    </transmission>

    <!-- EFFORT CONTROLLER -->
    <!-- <transmission name="trans_joint_1">
      <type>transmission_interface/SimpleTransmission</type>
      <joint name="joint_1">
        <hardwareInterface>hardware_interface/EffortJointInterface</hardwareInterface>
      </joint>
      <actuator name="joint_1_motor">
        <hardwareInterface>hardware_interface/EffortJointInterface</hardwareInterface>
        <mechanicalReduction>1</mechanicalReduction>
      </actuator>
    </transmission>

    <transmission name="trans_joint_2">
      <type>transmission_interface/SimpleTransmission</type>
      <joint name="joint_2">
        <hardwareInterface>hardware_interface/EffortJointInterface</hardwareInterface>
      </joint>
      <actuator name="joint_2_motor">
        <hardwareInterface>hardware_interface/EffortJointInterface</hardwareInterface>
        <mechanicalReduction>1</mechanicalReduction>
      </actuator>
    </transmission>

    <transmission name="trans_joint_3">
      <type>transmission_interface/SimpleTransmission</type>
      <joint name="joint_3">
        <hardwareInterface>hardware_interface/EffortJointInterface</hardwareInterface>
      </joint>
      <actuator name="joint_3_motor">
        <hardwareInterface>hardware_interface/EffortJointInterface</hardwareInterface>
        <mechanicalReduction>1</mechanicalReduction>
      </actuator>
    </transmission>

    <transmission name="trans_joint_4">
      <type>transmission_interface/SimpleTransmission</type>
      <joint name="joint_4">
        <hardwareInterface>hardware_interface/EffortJointInterface</hardwareInterface>
      </joint>
      <actuator name="joint_4_motor">
        <hardwareInterface>hardware_interface/EffortJointInterface</hardwareInterface>
        <mechanicalReduction>1</mechanicalReduction>
      </actuator>
    </transmission>
    
    <transmission name="trans_joint_5">
      <type>transmission_interface/SimpleTransmission</type>
      <joint name="joint_5">
        <hardwareInterface>hardware_interface/EffortJointInterface</hardwareInterface>
      </joint>
      <actuator name="joint_5_motor">
        <hardwareInterface>hardware_interface/EffortJointInterface</hardwareInterface>
        <mechanicalReduction>1</mechanicalReduction>
      </actuator>
    </transmission>

    <transmission name="trans_joint_6">
      <type>transmission_interface/SimpleTransmission</type>
      <joint name="joint_6">
        <hardwareInterface>hardware_interface/EffortJointInterface</hardwareInterface>
      </joint>
      <actuator name="joint_6_motor">
        <hardwareInterface>hardware_interface/EffortJointInterface</hardwareInterface>
        <mechanicalReduction>1</mechanicalReduction>
      </actuator>
    </transmission> -->

    <!-- Gazebo -->
    <gazebo>
      <plugin name="gazebo_ros_control" filename="libgazebo_ros_control.so">
        <robotNamespace>/</robotNamespace>
        <robotSimType>gazebo_ros_control/DefaultRobotHWSim</robotSimType>
        <legacyModeNS>true</legacyModeNS>
      </plugin>
    </gazebo>
</robot>
