<?xml version="1.0" ?>
<!-- =================================================================================== -->
<!-- |    This document was autogenerated by xacro from irb6640_185_280.xacro          | -->
<!-- |    EDITING THIS FILE BY HAND IS NOT RECOMMENDED                                 | -->
<!-- =================================================================================== -->
<robot name="abb_irb6640_185_280" xmlns:xacro="http://ros.org/wiki/xacro">
    <!-- link list -->
    <link name="base_link">
        <collision name="collision">
            <geometry>
                <mesh filename="package://abb_moveit_config/meshes/collision/base_link.stl" />
            </geometry>
        </collision>
        <visual name="visual">
            <geometry>
                <mesh filename="package://abb_moveit_config/meshes/visual/base_link.dae" />
            </geometry>
            <material name="yellow">
                <color rgba="1 1 0 1" />
            </material>
        </visual>
        
    <inertial>
            <mass value="500" />
            <inertia ixx="0.03" iyy="0.03" izz="0.03" ixy="0.0" ixz="0.0" iyz="0.0" />
        </inertial>

    </link>
    <link name="link_1">
        <collision name="collision">
            <geometry>
                <mesh filename="package://abb_moveit_config/meshes/collision/link_1.stl" />
            </geometry>
        </collision>
        <visual name="visual">
            <geometry>
                <mesh filename="package://abb_moveit_config/meshes/visual/link_1.dae" />
            </geometry>
            <material name="yellow" />
        </visual>
        
    <inertial>
            <mass value="0.1" />
            <inertia ixx="0.03" iyy="0.03" izz="0.03" ixy="0.0" ixz="0.0" iyz="0.0" />
        </inertial>

    </link>
    <link name="link_2">
        <collision name="collision">
            <geometry>
                <mesh filename="package://abb_moveit_config/meshes/collision/link_2.stl" />
            </geometry>
        </collision>
        <visual name="visual">
            <geometry>
                <mesh filename="package://abb_moveit_config/meshes/visual/link_2.dae" />
            </geometry>
            <material name="yellow" />
        </visual>
        
    <inertial>
            <mass value="0.1" />
            <inertia ixx="0.03" iyy="0.03" izz="0.03" ixy="0.0" ixz="0.0" iyz="0.0" />
        </inertial>

    </link>
    <link name="link_3">
        <collision name="collision">
            <geometry>
                <mesh filename="package://abb_moveit_config/meshes/collision/link_3.stl" />
            </geometry>
        </collision>
        <visual name="visual">
            <geometry>
                <mesh filename="package://abb_moveit_config/meshes/visual/link_3.dae" />
            </geometry>
            <material name="yellow" />
        </visual>
        
    <inertial>
            <mass value="0.1" />
            <inertia ixx="0.03" iyy="0.03" izz="0.03" ixy="0.0" ixz="0.0" iyz="0.0" />
        </inertial>

    </link>
    <link name="link_4">
        <collision name="collision">
            <geometry>
                <mesh filename="package://abb_moveit_config/meshes/collision/link_4.stl" />
            </geometry>
        </collision>
        <visual name="visual">
            <geometry>
                <mesh filename="package://abb_moveit_config/meshes/visual/link_4.dae" />
            </geometry>
            <material name="yellow" />
        </visual>
        
    <inertial>
            <mass value="0.1" />
            <inertia ixx="0.03" iyy="0.03" izz="0.03" ixy="0.0" ixz="0.0" iyz="0.0" />
        </inertial>

    </link>
    <link name="link_5">
        <collision name="collision">
            <geometry>
                <mesh filename="package://abb_moveit_config/meshes/collision/link_5.stl" />
            </geometry>
        </collision>
        <visual name="visual">
            <geometry>
                <mesh filename="package://abb_moveit_config/meshes/visual/link_5.dae" />
            </geometry>
            <material name="yellow" />
        </visual>
        
    <inertial>
            <mass value="0.1" />
            <inertia ixx="0.03" iyy="0.03" izz="0.03" ixy="0.0" ixz="0.0" iyz="0.0" />
        </inertial>

    </link>
    <link name="link_6">
        <collision name="collision">
            <geometry>
                <mesh filename="package://abb_moveit_config/meshes/collision/link_6.stl" />
            </geometry>
        </collision>
        <visual name="visual">
            <geometry>
                <mesh filename="package://abb_moveit_config/meshes/visual/link_6.dae" />
            </geometry>
            <material name="yellow" />
        </visual>
        
    <inertial>
            <mass value="0.1" />
            <inertia ixx="0.03" iyy="0.03" izz="0.03" ixy="0.0" ixz="0.0" iyz="0.0" />
        </inertial>

    </link>
    <link name="tool0" />
    <!--Cylinder and piston -->
    <link name="link_cylinder">
        <collision name="collision">
            <geometry>
                <mesh filename="package://abb_moveit_config/meshes/collision/cylinder_link.stl" />
            </geometry>
        </collision>
        <visual name="visual">
            <geometry>
                <mesh filename="package://abb_moveit_config/meshes/visual/cylinder_link.dae" />
            </geometry>
            <material name="yellow" />
        </visual>
        
    <inertial>
            <mass value="0.1" />
            <inertia ixx="0.03" iyy="0.03" izz="0.03" ixy="0.0" ixz="0.0" iyz="0.0" />
        </inertial>

    </link>
    <link name="link_piston">
        <collision name="collision">
            <geometry>
                <mesh filename="package://abb_moveit_config/meshes/collision/piston_link.stl" />
            </geometry>
        </collision>
        <visual name="visual">
            <geometry>
                <mesh filename="package://abb_moveit_config/meshes/visual/piston_link.dae" />
            </geometry>
            <material name="yellow" />
        </visual>
        
        <inertial>
            <mass value="0.1" />
            <inertia ixx="0.03" iyy="0.03" izz="0.03" ixy="0.0" ixz="0.0" iyz="0.0" />
        </inertial>

    </link>
    <!-- end of link list -->
    <!-- joint list -->
    <joint name="joint_1" type="revolute">
        <origin rpy="0 0 0" xyz="0 0 0.780" />
        <axis xyz="0 0 1" />
        <parent link="base_link" />
        <child link="link_1" />
        <limit effort="0" lower="-2.967" upper="2.967" velocity="1.7453" />
    </joint>
    <joint name="joint_2" type="revolute">
        <origin rpy="0 0 0" xyz="0.320 0 0" />
        <axis xyz="0 1 0" />
        <parent link="link_1" />
        <child link="link_2" />
        <limit effort="0" lower="-1.134" upper="1.4855" velocity="1.5707" />
    </joint>
    <joint name="joint_3" type="revolute">
        <origin rpy="0 0 0" xyz="0 0 1.075" />
        <axis xyz="0 1 0" />
        <parent link="link_2" />
        <child link="link_3" />
        <limit effort="0" lower="-3.142" upper="1.222" velocity="1.5707" />
    </joint>
    <joint name="joint_4" type="revolute">
        <origin rpy="0 0 0" xyz="0 0 0.2" />
        <axis xyz="1 0 0" />
        <parent link="link_3" />
        <child link="link_4" />
        <limit effort="0" lower="-5.236" upper="5.236" velocity="2.9671" />
    </joint>
    <joint name="joint_5" type="revolute">
        <origin rpy="0 0 0" xyz="1.392 0 0 " />
        <axis xyz="0 1 0" />
        <parent link="link_4" />
        <child link="link_5" />
        <limit effort="0" lower="-2.094" upper="2.094" velocity="2.4435" />
    </joint>
    <joint name="joint_6" type="revolute">
        <origin rpy="0 0 0" xyz="0.2 0 0 " />
        <axis xyz="1 0 0" />
        <parent link="link_5" />
        <child link="link_6" />
        <limit effort="0" lower="-6.283" upper="6.283" velocity="3.3161" />
    </joint>
    <joint name="joint_6-tool0" type="fixed">
        <parent link="link_6" />
        <child link="tool0" />
        <origin rpy="0 1.57079632679 0" xyz="0 0 0" />
    </joint>
    <joint name="joint_cylinder" type="continuous">
        <origin rpy="0 0 0" xyz="-0.3647 0 -0.1455" />
        <axis xyz="0 1 0" />
        <parent link="link_1" />
        <child link="link_cylinder" />
        <mimic joint="joint_2" multiplier="-0.25" />
    </joint>
    <joint name="joint_piston" type="continuous">
        <origin rpy="0 0 0" xyz="-0.22 0 -0.0672" />
        <axis xyz="0 1 0" />
        <parent link="link_2" />
        <child link="link_piston" />
        <mimic joint="joint_2" multiplier="-1.25" />
    </joint>
    <!-- end of joint list -->
    <!-- ROS base_link to ABB World Coordinates transform -->
    <link name="world" />
    <joint name="fixed" type="fixed">
        <origin rpy="0 0 0" xyz="0 0 0" />
        <parent link="world" />
        <child link="base_link" />
    </joint>
    
    <transmission name="trans_joint_1">
        <type>transmission_interface/SimpleTransmission</type>
        <joint name="joint_1">
            <hardwareInterface>hardware_interface/PositionJointInterface</hardwareInterface>
        </joint>
        <actuator name="joint_1_motor">
            <hardwareInterface>hardware_interface/PositionJointInterface</hardwareInterface>
            <mechanicalReduction>1</mechanicalReduction>
        </actuator>
    </transmission>
    <transmission name="trans_joint_2">
        <type>transmission_interface/SimpleTransmission</type>
        <joint name="joint_2">
            <hardwareInterface>hardware_interface/PositionJointInterface</hardwareInterface>
        </joint>
        <actuator name="joint_2_motor">
            <hardwareInterface>hardware_interface/EffortJointInterface</hardwareInterface>
            <mechanicalReduction>1</mechanicalReduction>
        </actuator>
    </transmission>
    <transmission name="trans_joint_3">
        <type>transmission_interface/SimpleTransmission</type>
        <joint name="joint_3">
            <hardwareInterface>hardware_interface/PositionJointInterface</hardwareInterface>
        </joint>
        <actuator name="joint_3_motor">
            <hardwareInterface>hardware_interface/PositionJointInterface</hardwareInterface>
            <mechanicalReduction>1</mechanicalReduction>
        </actuator>
    </transmission>
    <transmission name="trans_joint_4">
        <type>transmission_interface/SimpleTransmission</type>
        <joint name="joint_4">
            <hardwareInterface>hardware_interface/PositionJointInterface</hardwareInterface>
        </joint>
        <actuator name="joint_4_motor">
            <hardwareInterface>hardware_interface/PositionJointInterface</hardwareInterface>
            <mechanicalReduction>1</mechanicalReduction>
        </actuator>
    </transmission>
    <transmission name="trans_joint_5">
        <type>transmission_interface/SimpleTransmission</type>
        <joint name="joint_5">
            <hardwareInterface>hardware_interface/PositionJointInterface</hardwareInterface>
        </joint>
        <actuator name="joint_5_motor">
            <hardwareInterface>hardware_interface/PositionJointInterface</hardwareInterface>
            <mechanicalReduction>1</mechanicalReduction>
        </actuator>
    </transmission>
    <transmission name="trans_joint_6">
        <type>transmission_interface/SimpleTransmission</type>
        <joint name="joint_6">
            <hardwareInterface>hardware_interface/PositionJointInterface</hardwareInterface>
        </joint>
        <actuator name="joint_6_motor">
            <hardwareInterface>hardware_interface/PositionJointInterface</hardwareInterface>
            <mechanicalReduction>1</mechanicalReduction>
        </actuator>
    </transmission>
    <transmission name="trans_joint_cylinder">
        <type>transmission_interface/SimpleTransmission</type>
        <joint name="joint_cylinder">
            <hardwareInterface>hardware_interface/PositionJointInterface</hardwareInterface>
        </joint>
        <actuator name="joint_cylinder_motor">
            <hardwareInterface>hardware_interface/PositionJointInterface</hardwareInterface>
            <mechanicalReduction>1</mechanicalReduction>
        </actuator>
    </transmission>
    <transmission name="trans_joint_piston">
        <type>transmission_interface/SimpleTransmission</type>
        <joint name="joint_piston">
            <hardwareInterface>hardware_interface/PositionJointInterface</hardwareInterface>
        </joint>
        <actuator name="joint_piston_motor">
            <hardwareInterface>hardware_interface/PositionJointInterface</hardwareInterface>
            <mechanicalReduction>1</mechanicalReduction>
        </actuator>
    </transmission>
    <gazebo>
        <plugin name="gazebo_ros_control" filename="libgazebo_ros_control.so">
            <robotNamespace>abb_robot/</robotNamespace>
            <robotSimType>gazebo_ros_control/DefaultRobotHWSim</robotSimType>
        </plugin>
    </gazebo>
</robot>